Workbook

Sheet Charakterbogen
B1: Name | G1: Ferris | Y1: Attribute | AV1: Perk | BB1: BP | BD1: Effekt | BS1: Nachteile | BY1: BP | CA1: Effekt
B3: Rasse | G3: Lepurii/Volx | AV3: Flink | BD3: Vorteil eigenbewegung | BS3: Sozialphobie | BY3: 3 | CA3: interaktionen mit anderen nachteilig
Y4: Körper | AG4: =(AG7+AG9+AG11+AG13)/4 -> 0.25 | AJ4: Geist | AR4: =(AR7+AR9+AR11+AR13)/4 -> 2.5 | BD4: +4 Mobilität
B5: Größe | G5: 2 | AV5: Magiesicht | BD5: Fähigkeit magie zu erkennen | BS5: Vegetarisch | BY5: 2 | CA5: Fleisch verzehr ist verboten
B7: Gewicht | G7: 1 | Y7: Kraft | AG7: 0 | AJ7: Intelligenz | AR7: 4 | AV7: Flug lvl 2 | BD7: kann kurze distanz fliegen | BS7: Bunter Hund | BY7: 3 | CA7: andere erhalten eine zusätzliche Erfolgsstufe auf
CA8: Mustern/Menschenkenntnis-Würfe
Y9: Geschick | AG9: 0 | AJ9: Willenskraft | AR9: 2 | AV9: Ausdauernd | BB9: 2 | BD9: Weniger Malus durch längeres aufbleiben | BS9: Sleepyhead | BY9: 4 | CA9: braucht eine ZE mehr Schlaf
B10: 30 | E10: / | F10: =(1+G5+(AG4*G5)+(F16/10)) -> 30 | I10: HP | BD10: und körperlicher Aktionen
Q11: Bildoption | Y11: Zähigkeit | AG11: 0 | AJ11: Charisma | AR11: 2 | AV11: Stur | BB11: 3 | BD11: Willenskraft in Argumenten im Vorteil
B13: 9 | E13: / | F13: =(AR7+AR9+AR18) -> 9 | I13: MP | M13: Sprachen | Y13: Reflex | AG13: 1 | AJ13: Sinne | AR13: 2 | AV13: Magie Anwender | BB13: 4 | BD13: Erlaubt es Magie zu verwenden
M15: common | R15: Wildcard | AV15: Kalyz | BB15: 1 | BD15: +3 aether
B16: 3 | E16: / | F16: 265 | I16: Exp | M16: Lepuuri | AD16: Initiative: | AG16: =IF(G5=3,0+AG4/2,IF(G5=2,1+AG4/2,IF(G5=1,2+AG4/2,IF(G5=0,4+AG4/2,IF(G5=4,-1+AG4/2,IF(G5=5,-2+AG4/2,-4+AG4/2))))))+AG18 -> 6.125 | AJ16: Magie-Typus: | AO16: Natur | BD16: 2d4 aether regeneration
M17: Yuunga | AV17: Verstärkter Sinn (Sehen) | BB17: 3 | BD17: Mustern auf sehen im Vorteil
M18: Tiersprache | AD18: Bonus: | AG18: 5 | AO18: Bonus: | AR18: 3
AV19: Magischer Verstärker | BB19: 3 | BD19: Gelungene zauber eine stufe höher
B20: Paradigmen
Y21: Wohlbefinden | AM21: Lifeforce | AV21: Saisonaler Einklang | BB21: 5
E22: Schlafen | K22: Pride | Q22: Fashion
AB23: -1 Würfel | AM23: 2 | AO23: =((1+AG4)+(G5)) -> 3.25 | AQ23: 7 | AV23: Frühling | BB23: - | BD23: +2 auf Pflanzenkunde (Farming) oder
B24: Grad | E24: X | K24: X | Q24: X | AB24: -1 Vorteil | BD24: Tierkunde(Abrichten) | +1 Faith
B25: Brand | E25: X | Q25: X | S25: X | AB25: -1 Wurf Geist | AM25: Sanity | AV25: Sommer | BB25: - | BD25: [+4] "temporäre" HP / +1 Mobilität
B26: Daily | E26: X | Q26: X | R26: X
AB27: -1 Wurf Körper | AM27: 6 | AO27: =1+AR4+AR4 -> 6 | AV27: Herbst | BB27: - | BD27: +1 "Willpower"
B28: SE´s | BD28: +2 Bonus auf Wildnis oder Heimlichkeit
B29: Athletik | J29: 1 | M29: flink | U29: 1 | AB29: Bewegung - 1/3 | AM29: Faith | AV29: Winter | BB29: - | BD29: alle erhaltenen/gegebenen Heilungen [+1
B30: Mustern | J30: 4 | BD30: +2 Bonus auf Medizin oder Jäger
B31: Pflanzenkunde | J31: 1 | AB31: Initiative im Nachteil | AM31: 7 | AO31: =((1)+(AR7+AR9+AR11)/2)+2 -> 7 | AV31: Linguist x2 | BB31: 2 | BD31: 2 Common Sprachen, 1 exotic sprache
B32: Magiekunde | J32: 4
B33: Magiewirkung | J33: 15 | AB33: +/- 0
B34: Willensstärke | J34: 5
B35: Gaukelei/trickbetrug | J35: 1 | AB35: Initiative im Vorteil
B36: Klettern/Athletik | J36: 1
B37: Schreiber/maler | J37: 0 | AB37: Bewegung +1/3
B38: Weber | J38: 2
B39: Ausweichen | J39: 1 | AB39: +1 Wurf Körper/Geist
B40: Monster/unwesen | J40: 1
B41: Tierkunde | J41: 3 | AB41: +1 Wurf Geist/Körper
B42: Wildniss | J42: 2 | AA42: X
B43: Religion | J43: 1 | AB43: +1 Würfel
AB44: -1 Nachteil

Sheet Fertigkeiten
E5: Allgemein
V7: 1 | X7: 5 | Z7: 25 | AB7: 125 | AD7: SE benötigt
V9: 4 | X9: 20 | Z9: 100 | AB9: 375 | AD9: EXP benötigt
D12: Fertigkeit | V12: Attribut | AD12: + / - | AG12: Spezialisierung | BE12: Notizen
D15: Klettern / Athletik | V15: R | AD15: {=SUM(IF($BW$15:$BW$22=$V15,INDEX($BX$15:$BX$22,MATCH($V15,$BW$15:$BW$22,0)),0),IF($BW$15:$BW$22=$X15,INDEX($BX$15:$BX$22,MATCH($X15,$BW$15:$BW$22,0)),0),IF($BW$15:$BW$22=$Z15,INDEX($BX$15:$BX$22,MATCH($Z15,$BW$15:$BW$22,0)),0),IF($BW$15:$BW$22=$AB15,INDEX($BX$15:$BX$22,MATCH($AB15,$BW$15:$BW$22,0)),0))+BW24} -> 1.25 | AG15: Initiative | BE15: Anfangsattribut: Körper | BT15: =Charakterbogen!$J$14 -> 0 | BW15: K | BX15: =Charakterbogen!$AG$7 -> 0
BW16: G | BX16: =Charakterbogen!$AG$9 -> 0
D17: Schwimmen | AD17: {=SUM(IF($BW$15:$BW$22=$V17,INDEX($BX$15:$BX$22,MATCH($V17,$BW$15:$BW$22,0)),0),IF($BW$15:$BW$22=$X17,INDEX($BX$15:$BX$22,MATCH($X17,$BW$15:$BW$22,0)),0),IF($BW$15:$BW$22=$Z17,INDEX($BX$15:$BX$22,MATCH($Z17,$BW$15:$BW$22,0)),0),IF($BW$15:$BW$22=$AB17,INDEX($BX$15:$BX$22,MATCH($AB17,$BW$15:$BW$22,0)),0))+BW24} -> 0.25 | BE17: Anfangsattribut: Körper | BT17: =Charakterbogen!$J$14 -> 0 | BW17: Z | BX17: =Charakterbogen!$AG$11 -> 0
BW18: R | BX18: =Charakterbogen!$AG$13 -> 1
D19: Tanz und Akrobatik | AD19: {=SUM(IF($BW$15:$BW$22=$V19,INDEX($BX$15:$BX$22,MATCH($V19,$BW$15:$BW$22,0)),0),IF($BW$15:$BW$22=$X19,INDEX($BX$15:$BX$22,MATCH($X19,$BW$15:$BW$22,0)),0),IF($BW$15:$BW$22=$Z19,INDEX($BX$15:$BX$22,MATCH($Z19,$BW$15:$BW$22,0)),0),IF($BW$15:$BW$22=$AB19,INDEX($BX$15:$BX$22,MATCH($AB19,$BW$15:$BW$22,0)),0))} -> 0 | BE19: Anfangsattribut: Körper oder Charisma | BW19: I | BX19: =Charakterbogen!$AR$7 -> 4
BW20: W | BX20: =Charakterbogen!$AR$9 -> 2
D21: Gesang und Musizieren | AD21: {=SUM(IF($BW$15:$BW$22=$V21,INDEX($BX$15:$BX$22,MATCH($V21,$BW$15:$BW$22,0)),0),IF($BW$15:$BW$22=$X21,INDEX($BX$15:$BX$22,MATCH($X21,$BW$15:$BW$22,0)),0),IF($BW$15:$BW$22=$Z21,INDEX($BX$15:$BX$22,MATCH($Z21,$BW$15:$BW$22,0)),0),IF($BW$15:$BW$22=$AB21,INDEX($BX$15:$BX$22,MATCH($AB21,$BW$15:$BW$22,0)),0))} -> 0 | BE21: Anfangsattribut: freie Wahl | BW21: C | BX21: =Charakterbogen!$AR$11 -> 2
BW22: S | BX22: =Charakterbogen!$AR$13 -> 2
D23: Gaukelei und Trickbetrug | AD23: {=SUM(IF($BW$15:$BW$22=$V23,INDEX($BX$15:$BX$22,MATCH($V23,$BW$15:$BW$22,0)),0),IF($BW$15:$BW$22=$X23,INDEX($BX$15:$BX$22,MATCH($X23,$BW$15:$BW$22,0)),0),IF($BW$15:$BW$22=$Z23,INDEX($BX$15:$BX$22,MATCH($Z23,$BW$15:$BW$22,0)),0),IF($BW$15:$BW$22=$AB23,INDEX($BX$15:$BX$22,MATCH($AB23,$BW$15:$BW$22,0)),0))+BW24} -> 0.25 | BE23: Anfangsattribut: Körper | BT23: =Charakterbogen!$J$14 -> 0
BW24: =Charakterbogen!$AG$4 -> 0.25 | BY24: B
D25: Mustern und Menschenkenntnis | V25: I | X25: C | AD25: {=SUM(IF($BW$15:$BW$22=$V25,INDEX($BX$15:$BX$22,MATCH($V25,$BW$15:$BW$22,0)),0),IF($BW$15:$BW$22=$X25,INDEX($BX$15:$BX$22,MATCH($X25,$BW$15:$BW$22,0)),0),IF($BW$15:$BW$22=$Z25,INDEX($BX$15:$BX$22,MATCH($Z25,$BW$15:$BW$22,0)),0),IF($BW$15:$BW$22=$AB25,INDEX($BX$15:$BX$22,MATCH($AB25,$BW$15:$BW$22,0)),0))+BW26} -> 8.5 | AG25: Sinne, Beobachten | BE25: Anfangsattribut: Geist
BW26: =Charakterbogen!$AR$4 -> 2.5 | BY26: M
D27: Etikette und Redegewandheit | AD27: {=SUM(IF($BW$15:$BW$22=$V27,INDEX($BX$15:$BX$22,MATCH($V27,$BW$15:$BW$22,0)),0),IF($BW$15:$BW$22=$X27,INDEX($BX$15:$BX$22,MATCH($X27,$BW$15:$BW$22,0)),0),IF($BW$15:$BW$22=$Z27,INDEX($BX$15:$BX$22,MATCH($Z27,$BW$15:$BW$22,0)),0),IF($BW$15:$BW$22=$AB27,INDEX($BX$15:$BX$22,MATCH($AB27,$BW$15:$BW$22,0)),0))+BW26} -> 2.5 | BE27: Anfangsattribut: Geist
BW28: =Charakterbogen!$AR$11 -> 2 | BY28: CH
D29: Reiten | AD29: {=SUM(IF($BW$15:$BW$22=$V29,INDEX($BX$15:$BX$22,MATCH($V29,$BW$15:$BW$22,0)),0),IF($BW$15:$BW$22=$X29,INDEX($BX$15:$BX$22,MATCH($X29,$BW$15:$BW$22,0)),0),IF($BW$15:$BW$22=$Z29,INDEX($BX$15:$BX$22,MATCH($Z29,$BW$15:$BW$22,0)),0),IF($BW$15:$BW$22=$AB29,INDEX($BX$15:$BX$22,MATCH($AB29,$BW$15:$BW$22,0)),0))+BW24} -> 0.25 | BE29: Anfangsattribut: Körper | BT29: =Charakterbogen!$J$14 -> 0
D31: Fahrzeug lenken und Geräte bedienen | AD31: {=SUM(IF($BW$15:$BW$22=$V31,INDEX($BX$15:$BX$22,MATCH($V31,$BW$15:$BW$22,0)),0),IF($BW$15:$BW$22=$X31,INDEX($BX$15:$BX$22,MATCH($X31,$BW$15:$BW$22,0)),0),IF($BW$15:$BW$22=$Z31,INDEX($BX$15:$BX$22,MATCH($Z31,$BW$15:$BW$22,0)),0),IF($BW$15:$BW$22=$AB31,INDEX($BX$15:$BX$22,MATCH($AB31,$BW$15:$BW$22,0)),0))+BW24} -> 0.25 | BE31: Anfangsattribut: Körper | BT31: =Charakterbogen!$J$14 -> 0
D33: Schleichen, Verstecken und Heimlichkeit | AD33: {=SUM(IF($BW$15:$BW$22=$V33,INDEX($BX$15:$BX$22,MATCH($V33,$BW$15:$BW$22,0)),0),IF($BW$15:$BW$22=$X33,INDEX($BX$15:$BX$22,MATCH($X33,$BW$15:$BW$22,0)),0),IF($BW$15:$BW$22=$Z33,INDEX($BX$15:$BX$22,MATCH($Z33,$BW$15:$BW$22,0)),0),IF($BW$15:$BW$22=$AB33,INDEX($BX$15:$BX$22,MATCH($AB33,$BW$15:$BW$22,0)),0))+BW24} -> 0.25 | BE33: Anfangsattribut: Körper | BT33: =Charakterbogen!$J$14 -> 0
D35: Willensstärke | V35: I | AD35: {=SUM(IF($BW$15:$BW$22=$V35,INDEX($BX$15:$BX$22,MATCH($V35,$BW$15:$BW$22,0)),0),IF($BW$15:$BW$22=$X35,INDEX($BX$15:$BX$22,MATCH($X35,$BW$15:$BW$22,0)),0),IF($BW$15:$BW$22=$Z35,INDEX($BX$15:$BX$22,MATCH($Z35,$BW$15:$BW$22,0)),0),IF($BW$15:$BW$22=$AB35,INDEX($BX$15:$BX$22,MATCH($AB35,$BW$15:$BW$22,0)),0))+BW36} -> 4 | AG35: Eigensinn | BE35: Anfangsattribut: Geist
E39: Kampf
V41: 1 | X41: 5 | Z41: 25 | AB41: 125 | AD41: SE benötigt
V43: 4 | X43: 20 | Z43: 100 | AB43: 375 | AD43: EXP benötigt
D46: Fähigkeiten | V46: Attribut | AD46: + / - | AG46: Spezialisierung | BE46: Notizen
D49: Ausweichen | V49: R | AD49: {=SUM(IF($BW$15:$BW$22=$V49,INDEX($BX$15:$BX$22,MATCH($V49,$BW$15:$BW$22,0)),0),IF($BW$15:$BW$22=$X49,INDEX($BX$15:$BX$22,MATCH($X49,$BW$15:$BW$22,0)),0),IF($BW$15:$BW$22=$Z49,INDEX($BX$15:$BX$22,MATCH($Z49,$BW$15:$BW$22,0)),0),IF($BW$15:$BW$22=$AB49,INDEX($BX$15:$BX$22,MATCH($AB49,$BW$15:$BW$22,0)),0))+BW24} -> 1.25 | AG49: Reflexiv | BE49: Anfangsattribut: Körper | BT49: =Charakterbogen!$J$14 -> 0
D51: Nahkampf | AD51: {=SUM(IF($BW$15:$BW$22=$V51,INDEX($BX$15:$BX$22,MATCH($V51,$BW$15:$BW$22,0)),0),IF($BW$15:$BW$22=$X51,INDEX($BX$15:$BX$22,MATCH($X51,$BW$15:$BW$22,0)),0),IF($BW$15:$BW$22=$Z51,INDEX($BX$15:$BX$22,MATCH($Z51,$BW$15:$BW$22,0)),0),IF($BW$15:$BW$22=$AB51,INDEX($BX$15:$BX$22,MATCH($AB51,$BW$15:$BW$22,0)),0))+BW24} -> 0.25 | BE51: Anfangsattribut: Körper | BT51: =Charakterbogen!$J$14 -> 0
D53: Fernkampf | AD53: {=SUM(IF($BW$15:$BW$22=$V53,INDEX($BX$15:$BX$22,MATCH($V53,$BW$15:$BW$22,0)),0),IF($BW$15:$BW$22=$X53,INDEX($BX$15:$BX$22,MATCH($X53,$BW$15:$BW$22,0)),0),IF($BW$15:$BW$22=$Z53,INDEX($BX$15:$BX$22,MATCH($Z53,$BW$15:$BW$22,0)),0),IF($BW$15:$BW$22=$AB53,INDEX($BX$15:$BX$22,MATCH($AB53,$BW$15:$BW$22,0)),0))+BW24} -> 0.25 | BE53: Anfangsattribut: Körper | BT53: =Charakterbogen!$J$14 -> 0
D55: Führen, Taktik und Kriegskunst | AD55: {=SUM(IF($BW$15:$BW$22=$V55,INDEX($BX$15:$BX$22,MATCH($V55,$BW$15:$BW$22,0)),0),IF($BW$15:$BW$22=$X55,INDEX($BX$15:$BX$22,MATCH($X55,$BW$15:$BW$22,0)),0),IF($BW$15:$BW$22=$Z55,INDEX($BX$15:$BX$22,MATCH($Z55,$BW$15:$BW$22,0)),0),IF($BW$15:$BW$22=$AB55,INDEX($BX$15:$BX$22,MATCH($AB55,$BW$15:$BW$22,0)),0))+BW26} -> 2.5 | BE55: Anfangsattribut: Geist | BT55: =Charakterbogen!$J$14 -> 0
D57: Blocken mit Schilden | AD57: {=SUM(IF($BW$15:$BW$22=$V57,INDEX($BX$15:$BX$22,MATCH($V57,$BW$15:$BW$22,0)),0),IF($BW$15:$BW$22=$X57,INDEX($BX$15:$BX$22,MATCH($X57,$BW$15:$BW$22,0)),0),IF($BW$15:$BW$22=$Z57,INDEX($BX$15:$BX$22,MATCH($Z57,$BW$15:$BW$22,0)),0),IF($BW$15:$BW$22=$AB57,INDEX($BX$15:$BX$22,MATCH($AB57,$BW$15:$BW$22,0)),0))+BW24} -> 0.25 | BE57: Anfangsattribut: Körper | BT57: =Charakterbogen!$J$14 -> 0
D59: Kriegsmaschinerie | AD59: {=SUM(IF($BW$15:$BW$22=$V59,INDEX($BX$15:$BX$22,MATCH($V59,$BW$15:$BW$22,0)),0),IF($BW$15:$BW$22=$X59,INDEX($BX$15:$BX$22,MATCH($X59,$BW$15:$BW$22,0)),0),IF($BW$15:$BW$22=$Z59,INDEX($BX$15:$BX$22,MATCH($Z59,$BW$15:$BW$22,0)),0),IF($BW$15:$BW$22=$AB59,INDEX($BX$15:$BX$22,MATCH($AB59,$BW$15:$BW$22,0)),0))} -> 0 | BE59: Anfangsattribut: freie Wahl
D61: Magieanwendung | V61: I | X61: W | AD61: {=SUM(IF($BW$15:$BW$22=$V61,INDEX($BX$15:$BX$22,MATCH($V61,$BW$15:$BW$22,0)),0),IF($BW$15:$BW$22=$X61,INDEX($BX$15:$BX$22,MATCH($X61,$BW$15:$BW$22,0)),0),IF($BW$15:$BW$22=$Z61,INDEX($BX$15:$BX$22,MATCH($Z61,$BW$15:$BW$22,0)),0),IF($BW$15:$BW$22=$AB61,INDEX($BX$15:$BX$22,MATCH($AB61,$BW$15:$BW$22,0)),0))+BW26} -> 8.5 | AG61: Natur, Umgebung, Support | BE61: Anfangsattribut: Geist | BT61: =Charakterbogen!$W$14 -> 0
E65: Wissen
V67: 1 | X67: 5 | Z67: 25 | AB67: 125 | AD67: SE benötigt
V69: 4 | X69: 20 | Z69: 100 | AB69: 375 | AD69: EXP benötigt
D72: Fähigkeiten | V72: Attribut | AD72: + / - | AG72: Spezialisierung | BE72: Notizen
D75: Religion, Götter und Dämonen | AD75: {=SUM(IF($BW$15:$BW$22=$V75,INDEX($BX$15:$BX$22,MATCH($V75,$BW$15:$BW$22,0)),0),IF($BW$15:$BW$22=$X75,INDEX($BX$15:$BX$22,MATCH($X75,$BW$15:$BW$22,0)),0),IF($BW$15:$BW$22=$Z75,INDEX($BX$15:$BX$22,MATCH($Z75,$BW$15:$BW$22,0)),0),IF($BW$15:$BW$22=$AB75,INDEX($BX$15:$BX$22,MATCH($AB75,$BW$15:$BW$22,0)),0))+BW26} -> 2.5 | BE75: Anfangsattribut: Geist | BT75: =Charakterbogen!$J$14 -> 0
D77: Heraldik, Rechts- und Altertumskunde | AD77: {=SUM(IF($BW$15:$BW$22=$V77,INDEX($BX$15:$BX$22,MATCH($V77,$BW$15:$BW$22,0)),0),IF($BW$15:$BW$22=$X77,INDEX($BX$15:$BX$22,MATCH($X77,$BW$15:$BW$22,0)),0),IF($BW$15:$BW$22=$Z77,INDEX($BX$15:$BX$22,MATCH($Z77,$BW$15:$BW$22,0)),0),IF($BW$15:$BW$22=$AB77,INDEX($BX$15:$BX$22,MATCH($AB77,$BW$15:$BW$22,0)),0))+BW26} -> 2.5 | BE77: Anfangsattribut: Geist | BT77: =Charakterbogen!$W$14 -> 0
D79: Handel und Wertgegenstände | V79: I | AD79: {=SUM(IF($BW$15:$BW$22=$V79,INDEX($BX$15:$BX$22,MATCH($V79,$BW$15:$BW$22,0)),0),IF($BW$15:$BW$22=$X79,INDEX($BX$15:$BX$22,MATCH($X79,$BW$15:$BW$22,0)),0),IF($BW$15:$BW$22=$Z79,INDEX($BX$15:$BX$22,MATCH($Z79,$BW$15:$BW$22,0)),0),IF($BW$15:$BW$22=$AB79,INDEX($BX$15:$BX$22,MATCH($AB79,$BW$15:$BW$22,0)),0))+BW26} -> 6.5 | AG79: Mode | BE79: Anfangsattribut: Geist | BT79: =Charakterbogen!$W$14 -> 0
...

Sheet Inventar
B2: Inventar
B5: Geldbeutel
B7: Gulden | E7: Schilling | H7: Heller | K7: Pfifferling
B9: 0 | E9: 3 | H9: 1 | K9: 0
B12: Im Inventar | P12: PL | Q12: Anzahl | AH12: PL | AI12: Anzahl | AL12: Stoffe | AZ12: PL | BA12: Anzahl
B14: Rucksack | P14: 1 | Q14: 1 | T14: Antike-nagaii währung (2 Gold 5 Silber) | AL14: Xachivi Wool (Mag Resi) | AZ14: 1 | BA14: 35
B16: Werkzeugset (nähset mit nähmashine) +4 Auf schneidern | P16: 3 | Q16: 1 | AL16: Rolle-Weaver-Faden | AZ16: 3 | BA16: 1
B18: Klopflicht | P18: 1 | Q18: 1 | T18: SpellTome (verwaschen) (focus gegenstand) 0/3 ladungen | AH18: 3 | AI18: 1 | AL18: Wuppelfiber (weich orangefarbige seide) | AZ18: 1 | BA18: 13
B20: Zelt | P20: 1 | Q20: 1 | T20: Spelltome: 2/4 ladungen lightning (märchenbuch) Wolke als schlange dessen zunge ein blitz repräsentiert? | AH20: 2 | AI20: 1 | AL20: Traumwöllchen (begüstigt traum und visionen) Für schlafanzüge | AZ20: 5 | BA20: 12
B22: Getrocknete Früchte | P22: 1 | AL22: Fluffy-Wupple-Fur (Gives Fluffy Lv:1 on melee hit Roll d20 (14+ deal d8 Poison Dmg back) | AZ22: 3 | BA22: 1
B24: Flashe (Quellwasser) | P24: 0 | Q24: 4/5 | AL24: Wupple-Silk Feature: Smooth, (Glamor PL wird in social addiert) | AZ24: 4 | BA24: 6
B26: Fey Cap / Effect = random | P26: 3 | Q26: 1 | AL26: Starbrood-Collar-Membran (deko) | AZ26: 2 | BA26: 2
B28: Naturelementar Kristall (mittel) | P28: 4 | Q28: 1 | AL28: Starbrood-Faden (poison reduktion 2 pro pl) | AZ28: 3 | BA28: 2
B30: Woppelberrys | P30: 1 | Q30: 7 | AL30: Starbrood-Faden (poison reduktion 2 pro pl) | AZ30: 4 | BA30: 2
AL32: Starbrood Wing-Membrane On Hit: Poison-Cloud (d3 Poi Dmg) Will-Save (d20+10) / on Fail: (-1) roll next Turn | AZ32: 4 | BA32: 1
AL38: "Butterfly-Wing"/Teleport (1) On Worldmap: Teleport up to (1 ZE) closer to next City | AZ38: 4 | BA38: 2
AL40: In-k-oi Tinte (Maiz gelb) | AZ40: 2 | BA40: 1
B42: Pralinen | P42: 3 | Q42: 18 | AL42: Farbstoff (lila) | AZ42: 2 | BA42: 1
B44: Fischglas (In-k-oi) Tierkunde (ziel: 13 für tinte) (4/7) | P44: 2 | Q44: 1 | T44: Skizze: Gentelman Anzug Progress 54/60 | AH44: 3 | AI44: 1 | AL44: Farbstoff (weiß) | AZ44: 1 | BA44: 3
B46: Normales Fischfutter | P46: 1 | Q46: 25 | T46: Schreiberset (+3 schreiber/maler) | AH46: 2 | AI46: 1 | AL46: Farbstoff (Schwarz) | AZ46: 1 | BA46: 3
B48: Premium Futter (färbt tinte goldig) | P48: 2 | Q48: 9 | T48: Skizzenpapier (snittmuster) | AH48: 2 | AI48: 4 | AL48: Farbstoff (Himmelblau) | AZ48: 2 | BA48: 3
B53: Companion | P53: PL | Q53: Anzahl | AL53: Kleidung | AZ53: PL | BA53: Anzahl
B55: Wupple-Fibre-Larvae (Status: Loyal) Name: Dally Progress 12/40 Ernten: Woppelsilk | P55: 3 | Q55: 1
B57: Wupple-Fibre-Larvae (Status: Loyal) Name: Dilly Progress 11/40 Ernten: Woppelsilk | P57: 3 | Q57: 1

Sheet Magie
B2: Upgrade Tabelle
F5: Base | J5: Dice Up I | N5: Dice Up II | R5: Dice Up III | V5: Dice Up IV | Z5: Dice Up V
B7: Base | F7: 1d4 | J7: 1d6+1 | N7: 1d8+2 | R7: 1d10+3 | V7: 1d12+4 | Z7: 1d20+5
B9: Scale Up I | F9: 2d4 | J9: 2d6+1 | N9: 2d8+2 | R9: 2d10+3 | V9: 2d12+4 | Z9: 2d20+5
B11: Scale Up II | F11: 3d4 | J11: 3d6+1 | N11: 3d8+2 | R11: 3d10+3 | V11: 3d12+4 | Z11: 3d20+5
B13: Scale Up III | F13: 4d4 | J13: 4d6+1 | N13: 4d8+2 | R13: 4d10+3 | V13: 4d12+4 | Z13: 4d20+5
B15: Scale Up IV | F15: 5d4 | J15: 5d6+1 | N15: 5d8+2 | R15: 5d10+3 | V15: 5d12+4 | Z15: 5d20+5
B17: Scale Up V | F17: 6d4 | J17: 6d6+1 | N17: 6d8+2 | R17: 6d10+3 | V17: 6d12+4 | Z17: 6d20+5
B20: Magie
B23: Magieschule | L23: Info | W23: Vorbereiteter Zauber | AG23: Ladung | AJ23: Dauer | AM23: Effekt
B39: Regelfragen

Sheet Ausrüstung
C2: Ausrüstung
C5: Rüstung | M5: Physische-Resistenzen | U5: Elementare-Resistenzen
C7: Wo getragen: | G7: Name | K7: PL | M7: Kopf | O7: Brust | Q7: Arme | S7: Beine | U7: Feuer | W7: Wasser | Y7: Erde | AA7: Wind | AC7: Blitz | AE7: Eis | AG7: Säure | AI7: Licht | AK7: Dunkel | AM7: Haltbarkeit | AR7: Attribute / Sonderfertigkeiten
AO9: /
AO11: /
AO13: /
AO15: /
AO17: /
AO19: /
AO21: /
AO23: /
AO25: /
C27: Summe | M27: =SUM(M9,M11,M13,M15,M17,M21,M23,M25) -> 0 | O27: =SUM(O9,O11,O13,O15,O17,O21,O23,O25) -> 0 | Q27: =SUM(Q9,Q11,Q13,Q15,Q17,Q21,Q23,Q25) -> 0 | S27: =SUM(S9,S11,S13,S15,S17,S21,S23,S25) -> 0 | U27: =SUM(U9,U11,U13,U15,U17,U21,U23,U25) -> 0 | W27: =SUM(W9,W11,W13,W17,W15,W21,W23,W25) -> 0 | Y27: =SUM(Y9,Y11,Y13,Y15,Y17,Y21,Y23,Y25) -> 0 | AA27: =SUM(AA9,AA11,AA13,AA15,AA17,AA21,AA23,AA25) -> 0 | AC27: =SUM(AC9,AC11,AC13,AC15,AC17,AC21,AC23,AC25) -> 0 | AE27: =SUM(AE9,AE11,AE13,AE15,AE17,AE21,AE23,AE25) -> 0 | AG27: =SUM(AG9,AG11,AG13,AG15,AG17,AG21,AG23,AG25) -> 0 | AI27: =SUM(AI9,AI11,AI13,AI15,AI17,AI21,AI23,AI25) -> 0 | AK27: =SUM(AK9,AK11,AK13,AK15,AK17,AK21,AK23,AK25) -> 0
C31: Waffe | M31: Schadensart | T31: Physisch | AA31: Elementar
C33: Name | G33: Waffentyp | K33: PL | M33: Schnitt | O33: Stoß | Q33: Stich | T33: Würfel | X33: Bonus | AA33: Würfel | AE33: Element(e) | AI33: Bonus | AL33: Haltbarkeit | AQ33: Attribute / Sonderfertigkeiten
AN35: /
AN37: /
AN39: /
AN41: /
AN43: /
AN45: /
AN47: /
AN49: /
M53: Elementare-Boni / Affinitäten
M55: Feuer | O55: Wasser | Q55: Erde | S55: Wind | U55: Blitz | W55: Eis | Y55: Säure | AA55: Licht | AC55: Dunkel

Sheet Notizen
B2: Notizen
